Workbook

Sheet README
A1: R.R. Garden Booking & Rate Tracker
A3: Sheets in this workbook:
A4: 1. Guest Register — every individual booking from the handwritten register (name, ID details, dates, room). Currently loaded: Page 1 of 60 (12 bookings) as a working sample.
A5: 2. Hisaab Bookings — raw room-rate data (date + amount per room booked) from the June-July 2026 diary pages. This is the only rate data found in the scan.
A6: 3. Monthly Rate Trend — auto-calculated average/min/max rate and revenue per month, with a chart. Add more months to 'Hisaab Bookings' and it updates automatically.
A7: 4. Settlement Notes — the income-split scribbles under the June totals (Uncle/Ansh/Malwa/Online/Baki). Meaning is a best guess — please confirm.
A8: 5. Expenses — blank tracker for ongoing costs (repairs, supplies, staff etc.)
A10: IMPORTANT:
A11: - Yellow highlighted cells = handwriting was unclear in the scan. Please verify against the physical register before relying on them.
A12: - The register has ~700+ total bookings across 60 pages — only page 1 is digitized so far. Send more pages (clear, well-lit photos work best) and I'll keep adding rows.
A13: - Room rates only exist in the June/July diary — older register pages (Aug 2024 onward) record guest ID details but no price, so historical rate trend before May 2026 isn't available unless you have another rate record.

Sheet Guest Register
A1: R.R. Garden — Guest Register
A2: Digitized from handwritten register. Loaded: Page 1 (rows above) + pages 2-25 appended below (290 more bookings). Yellow cells = unclear handwriting (VERIFY) - check against physical register.
A4: PageNo | B4: SNo | C4: GuestName | D4: Age | E4: Relationship | F4: Nationality | G4: NumPersons | H4: Address | I4: Phone | J4: ComingFrom | K4: NextDestination | L4: Purpose | M4: ArrivalDateTime | N4: DepartureDateTime | O4: RoomNo
A5: 1 | B5: 1 | C5: Naitik Sharma / Aarti Rajput | D5: 21 / 11 | E5: Friend | F5: India | G5: 2 | H5: 175/2 Sanjay G.N. Naubasti, Gulab Nagar Naubasti, Kanpur | I5: 8229360908 | J5: Kalyanpur | K5: Kalyanpur | L5: Visit | M5: 8/11/24 7:20pm | N5: 8/11/24 8:10pm | O5: 201
A6: 1 | B6: 2 | C6: Abhay / Anjali | D6: 20 / 22 | E6: Friend | F6: India | G6: 2 | H6: 429 Bakfuri Purwa, 999 Devidhi Nagar | I6: 9696972862 | J6: Kanpur | K6: Kanpur | L6: Visit | M6: 9/11/24 12:35pm | N6: 9/11/24 4:20pm | O6: 201
A7: 1 | B7: 3 | C7: Sonu / Stuti | D7: 21 / 20 | E7: Friend | F7: India | G7: 2 | H7: Chak Bijay Harishpur, Lal Bagla Kanpur | I7: 6392813154 | J7: Kanpur | K7: Kanpur | L7: Visit | M7: 9/11/24 3:15pm | N7: 9/11/24 4:19pm | O7: 202
A8: 1 | B8: 4 | C8: Annu Tiwari / Ayush Sharma | D8: VERIFY / 19 | E8: Friend | F8: India | G8: 2 | H8: Naubasti Kanpur | I8: 6391189513 | J8: Kanpur | K8: Kanpur | L8: Visit | M8: 9/11/24 5:28pm | N8: 9/11/24 7:30pm | O8: 202
A9: 1 | B9: 5 | C9: Akshat / Roshani | D9: 20 / 22 | E9: Friend | F9: India | G9: 2 | H9: Dabauli Udyan Kanpur | I9: 7892064742 | J9: Kanpur | K9: Kanpur | L9: Visit | M9: 12/11/24 1:36pm | N9: 12/11/24 4:30pm | O9: 201
A10: 1 | B10: 6 | C10: Ram Prakash / Puja Singh | D10: VERIFY / 28 | E10: Friend | F10: India | G10: 2 | H10: Dada Nagar Kanpur | I10: 9909182961 | J10: Kanpur | K10: Kanpur | L10: Visit | M10: 12/11/24 2:20pm | N10: 12/11/24 5:30pm | O10: 202
A11: 1 | B11: 7 | C11: Ankit Rajput / Puja Soni | D11: 19 / 20 | E11: Friend | F11: India | G11: 2 | H11: Kathagar / Naubasti Kanpur | I11: 63866809 | J11: Kanpur | K11: Kanpur | L11: Visit | M11: 15/11/24 10:48am | N11: 15/11/24 1:28pm | O11: 202
A12: 1 | B12: 8 | C12: Vishal Rajput / Preeti | D12: 18 / 21 | E12: Friend | F12: India | G12: 2 | H12: Maal Kanpur / Kathagar Kanpur | I12: 6306078691 | J12: Kanpur | K12: Kanpur | L12: Visit | M12: 15/11/24 1:05pm | N12: 15/11/24 6:10pm | O12: 203
A13: 1 | B13: 9 | C13: Shweta / Ankit Singh | D13: 24 / 30 | E13: Friend | F13: India | G13: 2 | H13: Gram Berri Kalyanpur / Parsapur Purv Kanpur | I13: 8542845591 | J13: Kanpur | K13: Kanpur | L13: Visit | M13: 16/11/24 12:41pm | N13: 16/11/24 3:48pm | O13: 201
A14: 1 | B14: 10 | C14: Zeeshan / Umran Khatoon | D14: 43 / 38 | E14: Friend | F14: India | G14: 2 | H14: Kakadeo / Naubasti Kanpur | I14: 9696911758 | J14: Kanpur | K14: Kanpur | L14: Visit | M14: 19/11/24 7:15am | N14: 19/11/24 11:30am | O14: 201
A15: 1 | B15: 11 | C15: Ankit Kumar / Jyoti Yadav | D15: 28 / 26 | E15: Friend | F15: India | G15: 2 | H15: Panki / Kanpur Dehat | I15: VERIFY | J15: Kanpur | K15: Kanpur | L15: Visit | M15: 19/11/24 11:40am | N15: 19/11/24 2:30pm | O15: 202
A16: 1 | B16: 12 | C16: Abhay / Anjali | D16: 18 / 18 | E16: Friend | F16: India | G16: 2 | H16: 429 Bakchi Purwa / 999 Devidhi Nagar | I16: 9696972862 | J16: Kanpur | K16: Kanpur | L16: Visit | M16: 20/11/24 10:20am | N16: 20/11/24 4:40pm | O16: 201
A17: 2 | B17: 13 | C17: Utkarsh / Pooja | D17: 21 / 19 | E17: Friend | F17: Indian | G17: 2 | H17: Barra-8 / Barra-2 | I17: 6382679848 | J17: Kanpur | K17: Kanpur | L17: Visit | M17: 20/11/24 4:40pm | N17: 20/11/24 5:20pm | O17: 202
A18: 2 | B18: 14 | C18: Anurag / Jyoti | D18: 20 / 20 | E18: Friend | F18: Indian | G18: 2 | H18: C-684 World Bank Barra Kanpur / Barra-2 Kanpur | I18: 9335681286 | J18: Kanpur | K18: Kanpur | L18: Visit | M18: 20/11/24 4:52pm | N18: 20/11/24 8:10pm | O18: 203
A19: 2 | B19: 15 | C19: Balwan Singh / Ankita | D19: 27 / 23 | E19: Friend | F19: Indian | G19: 2 | H19: Yojana Nagar / Bhognipur Kanpur Dehat | I19: 8468061150 | J19: Kanpur | K19: Kanpur | L19: Visit | M19: 21/11/24 1:15pm | N19: 21/11/24 4:20pm | O19: 201
A20: 2 | B20: 16 | C20: Abhay Kumar / Sneha Pal | D20: 23 / 20 | E20: Friend | F20: Indian | G20: 2 | H20: Lal Bangla Kanpur | I20: VERIFY 6386717471 | J20: Kanpur | K20: Kanpur | L20: Visit | M20: 22/11/24 9:50am | N20: 22/11/24 1:15pm | O20: 201
A21: 2 | B21: 17 | C21: Sandeep Kumar / Saloni Rathore | D21: 20 / 21 | E21: Friend | F21: Indian | G21: 2 | H21: KP University, Kanpur Nagar | I21: 8957011856 | J21: Kanpur | K21: Kanpur | L21: Visit | M21: 23/11/24 12:42pm | N21: 23/11/24 4:43pm | O21: 202
A22: 2 | B22: 18 | C22: Divyansh Shukla / Ananya Mishra | D22: 20 / 21 | E22: Friend | F22: Indian | G22: 2 | H22: Naubasta / Naubasta Kanpur | I22: 9554346863 | J22: Kanpur | K22: Kanpur | L22: Visit | M22: 25/11/24 10:20am | N22: 25/11/24 2:10pm | O22: 202
A23: 2 | B23: 19 | C23: Alok Tiwari / Aarti Savita | D23: 20 / 34 | E23: Friend | F23: Indian | G23: 2 | H23: CTG Dabauli Kanpur / Ratanlal Nagar Kanpur | I23: 6392813154 | J23: Kanpur | K23: Kanpur | L23: Visit | M23: 25/11/24 12:28pm | N23: 25/11/24 7:17pm | O23: 201
A24: 2 | B24: 20 | C24: Pratham / Saloni | D24: 25 / 24 | E24: Friend | F24: Indian | G24: 2 | H24: T.P. Nagar Kanpur / T.P. Nagar | I24: 7905019018 | J24: Kanpur | K24: Kanpur | L24: Visit | M24: 25/11/24 12:20pm | N24: 25/11/24 2:30pm | O24: 204
A25: 2 | B25: 21 | C25: Abhay / Anjali | D25: 20 / 22 | E25: Friend | F25: Indian | G25: 2 | H25: 479 Bhaktauri Purwa / 499 Dwivedi Nagar | I25: 9696972862 | J25: Kanpur | K25: Kanpur | L25: Visit | M25: 28/11/24 1:04pm | N25: 28/11/24 5:50pm | O25: 203
A26: 2 | B26: 22 | C26: Abhay / Anjali | D26: 20 / 22 | E26: Friend | F26: Indian | G26: 2 | H26: 428 Bhaktauri Purwa / 421 Dwivedi Nagar | I26: 9696972862 | J26: Kanpur | K26: Kanpur | L26: Visit | M26: 28/11/24 4:50pm | N26: 29/11/24 9:50pm | O26: 202
A27: 2 | B27: 23 | C27: Alok Tiwari / Aarti Savita | D27: 20 / 21 | E27: Friend | F27: Indian | G27: 2 | H27: CTG Dabauli Kanpur / Ratanlal Nagar Kanpur | I27: 6392813154 | J27: Kanpur | K27: Kanpur | L27: Visit | M27: 28/11/24 7:10pm | N27: 29/11/24 9:55pm | O27: 203
A28: 2 | B28: 24 | C28: Sandeep Kumar / Saloni Rathore | D28: 20 / 21 | E28: Friend | F28: Indian | G28: 2 | H28: KP University Kanpur | I28: 8957011056 | J28: Kanpur | K28: Kanpur | L28: Visit | M28: 29/11/24 3:37pm | N28: 29/11/24 6:38pm | O28: 202
A29: 3 | B29: 25 | C29: Abhay / Anjali | D29: 20 / 21 | E29: Friend | F29: Indian | G29: 2 | H29: - | J29: Kanpur | K29: Kanpur | L29: Visit | M29: 29/11/24 6:10pm | N29: 29/11/24 10:01pm | O29: 202
A30: 3 | B30: 26 | C30: Zeeshan / Umran Khatoon | D30: 43 / 38 | E30: Friend | F30: Indian | G30: 2 | H30: Kakadeo Kanpur | J30: Kanpur | K30: Kanpur | L30: Visit | M30: 30/11/24 6:15am | N30: 30/11/24 9:58am | O30: 203
A31: 3 | B31: 27 | C31: Aman Verma / Sweta Pathak | D31: 19 / 19 | E31: Friend | F31: Indian (Passport BR02303975) | G31: 2 | H31: Rail Bazar Kanpur / Naubasta Kanpur | I31: 9451930495 | J31: Kanpur | K31: Kanpur | L31: Visit | M31: 30/11/24 8:17am | N31: 30/11/24 10:37am | O31: 202
A32: 3 | B32: 28 | C32: Krish Ranjan / Aditi Goda | D32: 26 / 20 | E32: Friend | F32: Indian | G32: 2 | H32: Burari New Delhi / Jhansi Mandi Road | I32: 9560087592 | J32: Delhi | K32: Delhi | L32: PSIT Counselling | M32: 30/11/24 8:55am | N32: 30/11/24 4:02pm | O32: 201
A33: 3 | B33: 29 | C33: Dolly / Harsh Siyen | D33: 20 / 20 | E33: Friend | F33: Indian | G33: 2 | H33: Sarigawan Kanpur | I33: 6386994805 | J33: Kanpur | K33: Kanpur | L33: Visit | M33: 30/11/24 9:38am | N33: 30/11/24 3:38pm | O33: 204
A34: 3 | B34: 30 | C34: Abhishek / Nainshi | D34: 21 / 21 | E34: Friend | F34: Indian | G34: 2 | H34: Kaindha Kanpur Nagar | I34: 9555655493 | J34: Kanpur | K34: Kanpur | L34: Visit | M34: 30/11/24 11:48am | N34: 30/11/24 5:40pm | O34: 205
A35: 3 | B35: 31 | C35: Prashant Gautam / Deeksha Katiyar | D35: 19 / 18 | E35: Friend | F35: Indian | G35: 2 | H35: Sikandra Kanpur Dehat | I35: 6388895511 | J35: Kanpur | K35: Kanpur | L35: Visit | M35: 1/12/24 1:20pm | N35: 1/12/24 4:40pm | O35: 202
A36: 3 | B36: 32 | C36: Ankit Rajput / Puja Soni | D36: 19 / 20 | E36: Friend | F36: Indian | G36: 2 | H36: Kathagar Kanpur / Naubasta Kanpur | I36: 6386680960 | J36: Kanpur | K36: Kanpur | L36: Visit | M36: 1/12/24 1:34pm | N36: 1/12/24 4:25pm | O36: 203
A37: 3 | B37: 33 | C37: Deepu Sonkar / Payal Yadav | D37: 21 / 22 | E37: Friend | F37: Indian | G37: 2 | H37: Mardanpur Kanpur Nagar | I37: 6394010145 | J37: Kanpur | K37: Kanpur | L37: Visit | M37: 1/12/24 2:15pm | N37: 1/12/24 5:02pm | O37: 204
A38: 3 | B38: 34 | C38: Ritik Kumar / Pooja | D38: 22 / 22 | E38: Friend | F38: Indian | G38: 2 | H38: Udhyog Nagar Kanpur / Barra Kanpur | I38: 9336648998 | J38: Kanpur | K38: Kanpur | L38: Visit | M38: 1/12/24 4:08pm | N38: 1/12/24 4:30pm | O38: 201
A39: 3 | B39: 35 | C39: Pushpendra Pal | D39: 28 | E39: Friend | F39: Indian | G39: 1 | H39: Barra Kanpur | J39: Kanpur | K39: Kanpur | L39: Visit | M39: 2/12/24 1:15pm | N39: 2/12/24 5:15pm | O39: 202
A40: 3 | B40: 36 | C40: Amit Pal / Sakshi Tiwari | D40: 25 / 23 | E40: Friend | F40: Indian | G40: 2 | H40: Jarauli P-2 Kanpur / World Bank Barra-2 | I40: 7380621774 | J40: Kanpur | K40: Kanpur | L40: Visit | M40: 4/12/24 12:08pm | N40: 4/12/24 7:10pm | O40: 202
A41: 4 | B41: 37 | C41: Santosh Diwakar / Jyoti | D41: 24 / 24 | E41: Friend | F41: Indian | G41: 2 | H41: Juhi Colony Kanpur | I41: 8858377720 | J41: Kanpur | K41: Kanpur | L41: Visit | M41: 4/12/24 12:50pm | N41: 4/12/24 3:10pm | O41: 203
...

Sheet Hisaab Bookings
A1: R.R. Garden — Room Rate Ledger (raw bookings, from June–July 2026 diary pages)
A2: Each row = one room booking on that date. Source: handwritten diary, last 2 pages of scan.
A4: Date | B4: Amount
A5: 2026-05-31 | B5: 800
A6: 2026-06-01 | B6: 800
A7: 2026-06-03 | B7: 600
A8: 2026-06-04 | B8: 600
A9: 2026-06-05 | B9: 500
A10: 2026-06-05 | B10: 500
A11: 2026-06-07 | B11: 650
A12: 2026-06-07 | B12: 630
A13: 2026-06-07 | B13: 600
A14: 2026-06-07 | B14: 600
A15: 2026-06-10 | B15: 600
A16: 2026-06-13 | B16: 530
... A47: 2026-07-04 | B47: 520

Sheet Monthly Rate Trend
A1: R.R. Garden — Monthly Room Rate Trend
A2: Auto-calculated from "Hisaab Bookings" sheet using AVERAGEIFS/COUNTIFS/MIN/MAXIFS. Add new months to Hisaab Bookings and this updates automatically.
A4: Month | B4: Bookings | C4: Avg Rate (Rs) | D4: Min Rate (Rs) | E4: Max Rate (Rs) | F4: Total Revenue (Rs)
A5: May 2026 | B5: =COUNTIFS('Hisaab Bookings'!$A$5:$A$47,">="&DATE(2026,5,1),'Hisaab Bookings'!$A$5:$A$47,"<="&DATE(2026,5,31)) | C5: =IFERROR(AVERAGEIFS('Hisaab Bookings'!$B$5:$B$47,'Hisaab Bookings'!$A$5:$A$47,">="&DATE(2026,5,1),'Hisaab Bookings'!$A$5:$A$47,"<="&DATE(2026,5,31)),0) | D5: =IFERROR(minifs('Hisaab Bookings'!$B$5:$B$47,'Hisaab Bookings'!$A$5:$A$47,">="&DATE(2026,5,1),'Hisaab Bookings'!$A$5:$A$47,"<="&DATE(2026,5,31)),0) | E5: =IFERROR(maxifs('Hisaab Bookings'!$B$5:$B$47,'Hisaab Bookings'!$A$5:$A$47,">="&DATE(2026,5,1),'Hisaab Bookings'!$A$5:$A$47,"<="&DATE(2026,5,31)),0) | F5: =IFERROR(SUMIFS('Hisaab Bookings'!$B$5:$B$47,'Hisaab Bookings'!$A$5:$A$47,">="&DATE(2026,5,1),'Hisaab Bookings'!$A$5:$A$47,"<="&DATE(2026,5,31)),0)
A6: June 2026 | B6: =COUNTIFS('Hisaab Bookings'!$A$5:$A$47,">="&DATE(2026,6,1),'Hisaab Bookings'!$A$5:$A$47,"<="&DATE(2026,6,30)) | C6: =IFERROR(AVERAGEIFS('Hisaab Bookings'!$B$5:$B$47,'Hisaab Bookings'!$A$5:$A$47,">="&DATE(2026,6,1),'Hisaab Bookings'!$A$5:$A$47,"<="&DATE(2026,6,30)),0) | D6: =IFERROR(minifs('Hisaab Bookings'!$B$5:$B$47,'Hisaab Bookings'!$A$5:$A$47,">="&DATE(2026,6,1),'Hisaab Bookings'!$A$5:$A$47,"<="&DATE(2026,6,30)),0) | E6: =IFERROR(maxifs('Hisaab Bookings'!$B$5:$B$47,'Hisaab Bookings'!$A$5:$A$47,">="&DATE(2026,6,1),'Hisaab Bookings'!$A$5:$A$47,"<="&DATE(2026,6,30)),0) | F6: =IFERROR(SUMIFS('Hisaab Bookings'!$B$5:$B$47,'Hisaab Bookings'!$A$5:$A$47,">="&DATE(2026,6,1),'Hisaab Bookings'!$A$5:$A$47,"<="&DATE(2026,6,30)),0)
A7: July 2026 | B7: =COUNTIFS('Hisaab Bookings'!$A$5:$A$47,">="&DATE(2026,7,1),'Hisaab Bookings'!$A$5:$A$47,"<="&DATE(2026,7,31)) | C7: =IFERROR(AVERAGEIFS('Hisaab Bookings'!$B$5:$B$47,'Hisaab Bookings'!$A$5:$A$47,">="&DATE(2026,7,1),'Hisaab Bookings'!$A$5:$A$47,"<="&DATE(2026,7,31)),0) | D7: =IFERROR(minifs('Hisaab Bookings'!$B$5:$B$47,'Hisaab Bookings'!$A$5:$A$47,">="&DATE(2026,7,1),'Hisaab Bookings'!$A$5:$A$47,"<="&DATE(2026,7,31)),0) | E7: =IFERROR(maxifs('Hisaab Bookings'!$B$5:$B$47,'Hisaab Bookings'!$A$5:$A$47,">="&DATE(2026,7,1),'Hisaab Bookings'!$A$5:$A$47,"<="&DATE(2026,7,31)),0) | F7: =IFERROR(SUMIFS('Hisaab Bookings'!$B$5:$B$47,'Hisaab Bookings'!$A$5:$A$47,">="&DATE(2026,7,1),'Hisaab Bookings'!$A$5:$A$47,"<="&DATE(2026,7,31)),0)
A8: All-time (loaded data) | B8: =COUNT('Hisaab Bookings'!$B$5:$B$47) | C8: =AVERAGE('Hisaab Bookings'!$B$5:$B$47) | D8: =MIN('Hisaab Bookings'!$B$5:$B$47) | E8: =MAX('Hisaab Bookings'!$B$5:$B$47) | F8: =SUM('Hisaab Bookings'!$B$5:$B$47)

Sheet Settlement Notes
A1: R.R. Garden — Income Split / Settlement Notes (from diary)
A2: These are running settlement notes found under the June/July totals — meaning not 100% certain, please confirm. Likely a split of room income between people (Uncle, Ansh, Malwa) plus online vs cash tracking and balance due.
A4: June (first half, 31 May – 14 Jun)
A5: Total | B5: 10930
A6: Uncle | B6: 8100
A7: Ansh | B7: 900
A8: Malwa | B8: 1000
A9: Online | B9: 700
A10: Baki hai (balance due) | B10: 200
A12: June (second half, 15–30 Jun)
A13: Total | B13: 11830
A14: Uncle+Ansh | B14: 1050
A15: Malwa | B15: 2000
A16: VERIFY (unclear label) | B16: 700
A17: VERIFY (unclear label) | B17: 170
A18: Dena hai (to be paid) | B18: 2010
A19: Baki (balance due) | B19: 200
A20: Total settlement | B20: 2810

Sheet Expenses
A1: R.R. Garden — Expenses Tracker
A2: Log ongoing expenses here (repairs, supplies, staff, electricity, etc.) to net against booking revenue.
A4: Date | B4: Category | C4: Description | D4: Amount (Rs) | E4: Paid By | F4: Notes
C41: Total | D41: =SUM(D5:D40)

Sheet Monthly Bookings & Ansh
A1: Monthly Bookings & Ansh Commission
A2: Booking count from Guest Register ArrivalDateTime. Commission = Rs 50/booking; manager remits within 15 days minus commission.
A4: Month | B4: Bookings | C4: Commission (Rs 50/booking)
A5: 11/2024 | B5: =COUNTIF('Guest Register'!$M$5:$M$10000,"*/11/24 *")+COUNTIF('Guest Register'!$M$5:$M$10000,"*/11/24") | C5: =B5*50
A6: 12/2024 | B6: =COUNTIF('Guest Register'!$M$5:$M$10000,"*/12/24 *")+COUNTIF('Guest Register'!$M$5:$M$10000,"*/12/24") | C6: =B6*50
A7: 01/2025 | B7: =COUNTIF('Guest Register'!$M$5:$M$10000,"*/1/25 *")+COUNTIF('Guest Register'!$M$5:$M$10000,"*/1/25")+COUNTIF('Guest Register'!$M$5:$M$10000,"*/01/25 *")+COUNTIF('Guest Register'!$M$5:$M$10000,"*/01/25") | C7: =B7*50
A8: 02/2025 | B8: =COUNTIF('Guest Register'!$M$5:$M$10000,"*/2/25 *")+COUNTIF('Guest Register'!$M$5:$M$10000,"*/2/25")+COUNTIF('Guest Register'!$M$5:$M$10000,"*/02/25 *")+COUNTIF('Guest Register'!$M$5:$M$10000,"*/02/25") | C8: =B8*50
A9: 03/2025 | B9: =COUNTIF('Guest Register'!$M$5:$M$10000,"*/3/25 *")+COUNTIF('Guest Register'!$M$5:$M$10000,"*/3/25")+COUNTIF('Guest Register'!$M$5:$M$10000,"*/03/25 *")+COUNTIF('Guest Register'!$M$5:$M$10000,"*/03/25") | C9: =B9*50
A10: 04/2025 | B10: =COUNTIF('Guest Register'!$M$5:$M$10000,"*/4/25 *")+COUNTIF('Guest Register'!$M$5:$M$10000,"*/4/25")+COUNTIF('Guest Register'!$M$5:$M$10000,"*/04/25 *")+COUNTIF('Guest Register'!$M$5:$M$10000,"*/04/25") | C10: =B10*50
A11: 05/2025 | B11: =COUNTIF('Guest Register'!$M$5:$M$10000,"*/5/25 *")+COUNTIF('Guest Register'!$M$5:$M$10000,"*/5/25")+COUNTIF('Guest Register'!$M$5:$M$10000,"*/05/25 *")+COUNTIF('Guest Register'!$M$5:$M$10000,"*/05/25") | C11: =B11*50
A12: 06/2025 | B12: =COUNTIF('Guest Register'!$M$5:$M$10000,"*/6/25 *")+COUNTIF('Guest Register'!$M$5:$M$10000,"*/6/25")+COUNTIF('Guest Register'!$M$5:$M$10000,"*/06/25 *")+COUNTIF('Guest Register'!$M$5:$M$10000,"*/06/25") | C12: =B12*50
A13: 07/2025 | B13: =COUNTIF('Guest Register'!$M$5:$M$10000,"*/7/25 *")+COUNTIF('Guest Register'!$M$5:$M$10000,"*/7/25")+COUNTIF('Guest Register'!$M$5:$M$10000,"*/07/25 *")+COUNTIF('Guest Register'!$M$5:$M$10000,"*/07/25") | C13: =B13*50
A14: 08/2025 | B14: =COUNTIF('Guest Register'!$M$5:$M$10000,"*/8/25 *")+COUNTIF('Guest Register'!$M$5:$M$10000,"*/8/25")+COUNTIF('Guest Register'!$M$5:$M$10000,"*/08/25 *")+COUNTIF('Guest Register'!$M$5:$M$10000,"*/08/25") | C14: =B14*50
A15: 09/2025 | B15: =COUNTIF('Guest Register'!$M$5:$M$10000,"*/9/25 *")+COUNTIF('Guest Register'!$M$5:$M$10000,"*/9/25")+COUNTIF('Guest Register'!$M$5:$M$10000,"*/09/25 *")+COUNTIF('Guest Register'!$M$5:$M$10000,"*/09/25") | C15: =B15*50
A16: 10/2025 | B16: =COUNTIF('Guest Register'!$M$5:$M$10000,"*/10/25 *")+COUNTIF('Guest Register'!$M$5:$M$10000,"*/10/25") | C16: =B16*50
A17: 11/2025 | B17: =COUNTIF('Guest Register'!$M$5:$M$10000,"*/11/25 *")+COUNTIF('Guest Register'!$M$5:$M$10000,"*/11/25") | C17: =B17*50
A18: 12/2025 | B18: =COUNTIF('Guest Register'!$M$5:$M$10000,"*/12/25 *")+COUNTIF('Guest Register'!$M$5:$M$10000,"*/12/25") | C18: =B18*50
A19: 01/2026 | B19: =COUNTIF('Guest Register'!$M$5:$M$10000,"*/1/26 *")+COUNTIF('Guest Register'!$M$5:$M$10000,"*/1/26")+COUNTIF('Guest Register'!$M$5:$M$10000,"*/01/26 *")+COUNTIF('Guest Register'!$M$5:$M$10000,"*/01/26") | C19: =B19*50
A20: 02/2026 | B20: =COUNTIF('Guest Register'!$M$5:$M$10000,"*/2/26 *")+COUNTIF('Guest Register'!$M$5:$M$10000,"*/2/26")+COUNTIF('Guest Register'!$M$5:$M$10000,"*/02/26 *")+COUNTIF('Guest Register'!$M$5:$M$10000,"*/02/26") | C20: =B20*50
A21: 03/2026 | B21: =COUNTIF('Guest Register'!$M$5:$M$10000,"*/3/26 *")+COUNTIF('Guest Register'!$M$5:$M$10000,"*/3/26")+COUNTIF('Guest Register'!$M$5:$M$10000,"*/03/26 *")+COUNTIF('Guest Register'!$M$5:$M$10000,"*/03/26") | C21: =B21*50
A22: 04/2026 | B22: =COUNTIF('Guest Register'!$M$5:$M$10000,"*/4/26 *")+COUNTIF('Guest Register'!$M$5:$M$10000,"*/4/26")+COUNTIF('Guest Register'!$M$5:$M$10000,"*/04/26 *")+COUNTIF('Guest Register'!$M$5:$M$10000,"*/04/26") | C22: =B22*50
A23: 05/2026 | B23: =COUNTIF('Guest Register'!$M$5:$M$10000,"*/5/26 *")+COUNTIF('Guest Register'!$M$5:$M$10000,"*/5/26")+COUNTIF('Guest Register'!$M$5:$M$10000,"*/05/26 *")+COUNTIF('Guest Register'!$M$5:$M$10000,"*/05/26") | C23: =B23*50
A24: 06/2026 | B24: =COUNTIF('Guest Register'!$M$5:$M$10000,"*/6/26 *")+COUNTIF('Guest Register'!$M$5:$M$10000,"*/6/26")+COUNTIF('Guest Register'!$M$5:$M$10000,"*/06/26 *")+COUNTIF('Guest Register'!$M$5:$M$10000,"*/06/26") | C24: =B24*50
A25: 07/2026 | B25: =COUNTIF('Guest Register'!$M$5:$M$10000,"*/7/26 *")+COUNTIF('Guest Register'!$M$5:$M$10000,"*/7/26")+COUNTIF('Guest Register'!$M$5:$M$10000,"*/07/26 *")+COUNTIF('Guest Register'!$M$5:$M$10000,"*/07/26") | C25: =B25*50
A26: TOTAL | B26: =SUM(B5:B25) | C26: =SUM(C5:C25)
